Workbook

Sheet HELP
A1: Sheet | B1: Data | C1: Description | D1: DataProvider
A2: Meta_Data | B2: Summary | C2: Overview of the dimensions of the dataset and its purpose | D2: NA
A3: Catch | B3: Total catches in weight by fleet, area and season. | C3: Weight units must match weight at age (WAA) historical catches (Hist_Catch) etc. | D3: Secretariat
A4: Hist_Catch | B4: Spool-up catches in weight prior to Catch dataset | C4: Catches prior to the modern fishery where other data sources such as length compositions and indices are not available to estimate recruitment. | D4: Secretariat
A5: Indices | B5: Definition of the abundance indices | C5: The list of indices (CPUE and survey) used in the models | D5: Secretariat
A6: CPUE | B6: Fishery-dependent indices of vulnerable biomass | C6: Len_cat is the length category (a range of lengths) defined in the sheet 'CPUE_Vuln'. A value of zero is 'no length category' and this mean all length classes are used to calculate vulnerable biomass | D6: Secretariat
A7: Survey | B7: Fishery-independent indices of spawning or total biomass | C7: Type is either 'B' (total biomass) or 'SB' (total spawning biomass) | D7: Secretariat
A8: E_Tag | B8: Electronic tagging data | C8: Structured as the fraction or number moving from a previous season to this season (ie the season field is the season tags are moving 'to'). Age_class refers to a range of ages defined in sheet Age_classes | D8: Lauretta
A9: Length_Comp | B9: Length composition data | C9: Len_class corresponds with the bins defined in Length_classes (Length_classes are the bin definitions, ie there are nlengthclasses + 1 lengths in the Length_classes sheet) | D9: Secretariat
A10: SOO | B10: Stock of origin observations | C10: Information about the fraction of fish of a particular stock of origin. Age_class refers to a range of ages defined in sheet Age_classes | D10: Alex
A11: CKMR_POP | B11: CKMR Parent-Offspring-Pair | C11: Yet to be finalized | D11: Lauretta
A12: CKMR_HSP | B12: CKMR Half-Sibling-Pair | C12: Yet to be finalized | D12: Lauretta
... A26: Spawn_areas | B26: In what areas can each stock spawn? | C26: Whether spawning can or cannot occur (boolean) indicated by a zero (cannot spawn) or a 1 (can spawn). | D26: NA
A27: MAA | B27: Instantaneous annual natural mortality rate at age | D27: NA
A28: Mov_Exc | B28: Movement exclusion matrix | C28: Which seasonal transitions do not need to be estimated? This includes, for example any western fish into the Mediterranean but also can include any transitions never observed in tagging. | D28: NA

Sheet Meta_Data
A1: Name | B1: MSA_demo
A2: Date | B2: 46121
A3: Author | B3: BlueMatter
A4: Notes | B4: For demonstration purposes
A5: Source | B5: ICCAT
A6: Year0 | B6: 1864
A7: First_year | B7: 1965
A8: Last_year | B8: 2019
A9: n_stocks | B9: 2
A10: Stock_names | B10: Eastern, Western
A11: n_lengths | B11: 15
A12: n_ages | B12: 35
A13: n_areas | B13: 4
A14: n_fleets | B14: 18
A15: n_seasons | B15: 4
A16: n_CPUE | B16: 19
A17: n_Survey | B17: 7
A18: Weight_unit | B18: kg
A19: Length_unit | B19: cm

Sheet Catch
A1: Year | B1: Season | C1: Area | D1: Fleet | E1: Catch
A2: 1972 | B2: 2 | C2: 1 | D2: 1 | E2: 6.46875
A3: 1973 | B3: 1 | C3: 1 | D3: 1 | E3: 0.019164068
A4: 1973 | B4: 2 | C4: 1 | D4: 1 | E4: 0.012830354
A5: 1973 | B5: 3 | C5: 1 | D5: 1 | E5: 1.0197395
A6: 1973 | B6: 4 | C6: 1 | D6: 1 | E6: 0.00089608822
A7: 1974 | B7: 1 | C7: 1 | D7: 1 | E7: 0.54614045
A8: 1974 | B8: 2 | C8: 1 | D8: 1 | E8: 0.36564132
A9: 1974 | B9: 3 | C9: 1 | D9: 1 | E9: 0.06268137
A10: 1974 | B10: 4 | C10: 1 | D10: 1 | E10: 0.025536854
A11: 1975 | B11: 1 | C11: 1 | D11: 1 | E11: 0.13787
A12: 1975 | B12: 2 | C12: 1 | D12: 1 | E12: 27.26161
A13: 1976 | B13: 1 | C13: 1 | D13: 1 | E13: 2.3570275
... A4250: 2024 | B4250: 4 | C4250: 3 | D4250: 18 | E4250: 2823.8107

Sheet Hist_Catch
A1: Year | B1: Season | C1: Area | D1: Age | E1: Catch
A2: 1963 | B2: 4 | C2: 1 | D2: 4 | E2: 0.00047544443
A3: 1963 | B3: 4 | C3: 1 | D3: 5 | E3: 0.00028150268
A4: 1963 | B4: 4 | C4: 1 | D4: 6 | E4: 0.00058848891
A5: 1963 | B5: 4 | C5: 1 | D5: 7 | E5: 0.0034499026
A6: 1963 | B6: 4 | C6: 1 | D6: 8 | E6: 0.014712348
A7: 1963 | B7: 4 | C7: 1 | D7: 9 | E7: 0.031649338
A8: 1963 | B8: 4 | C8: 1 | D8: 10 | E8: 0.052154968
A9: 1963 | B9: 4 | C9: 1 | D9: 11 | E9: 0.067897596
A10: 1963 | B10: 4 | C10: 1 | D10: 12 | E10: 0.076859582
A11: 1963 | B11: 4 | C11: 1 | D11: 13 | E11: 0.077138079
A12: 1963 | B12: 4 | C12: 1 | D12: 14 | E12: 0.071698151
A13: 1963 | B13: 4 | C13: 1 | D13: 15 | E13: 0.064411666
... A8751: 1964 | B8751: 4 | C8751: 4 | D8751: 35 | E8751: 0.05948347

Sheet Indices
A1: Region | B1: Index | C1: Area4Name | D1: Area4 | E1: Area7 | F1: FirstYear | G1: EndYear | H1: Missing years | I1: AK note Apr2026
A2: East | B2: SPN_BB | C2: EATL | D2: 3 | E2: 6 | F2: 1952 | G2: 2006 | H2: NA | I2: OK
A3: East | B3: SPN_FR_BB | C3: EATL | D3: 3 | E3: 6 | F3: 2007 | G3: 2014 | H3: NA | I3: OK
A4: East | B4: MOR_SPN_TRAP | C4: EATL | D4: 3 | E4: 4 | F4: 1981 | G4: 2011 | H4: NA | I4: OK
A5: East | B5: MOR_POR_TRAP | C5: EATL | D5: 3 | E5: 4 | F5: 2012 | G5: 2024 | H5: NA | I5: OK
A6: East | B6: JPN_LL_Eatl_Med | C6: EATL | D6: 3 | E6: 4 | F6: 1975 | G6: 2009 | H6: NA | I6: OK
A7: East | B7: JPN_LL_NEAtl1 | C7: EATL | D7: 3 | E7: 5 | F7: 1990 | G7: 2009 | H7: NA | I7: OK
A8: East | B8: JPN_LL_NEAtl2 | C8: EATL | D8: 3 | E8: 5 | F8: 2010 | G8: 2024 | H8: NA | I8: OK
A9: East | B9: FR_AER_SUV1 | C9: MED | D9: 4 | E9: 7 | F9: 2000 | G9: 2003 | H9: NA | I9: OK
A10: East | B10: FR_AER_SUV2 | C10: MED | D10: 4 | E10: 7 | F10: 2009 | G10: 2024 | H10: 2013 | I10: OK
A11: East | B11: MED_LAR_SUV | C11: MED | D11: 4 | E11: 7 | F11: 2001 | G11: 2024 | H11: 2006, 2007, 2009, 2010, 2018, 2021 | I11: OK
A12: East | B12: GBYP_AER_SUV_BAR | C12: MED | D12: 4 | E12: 7 | F12: 2010 | G12: 2024 | H12: 2012, 2014, 2016, 2020 | I12: OK
A13: West | B13: US_RR_66_144 | C13: WATL | D13: 2 | E13: 2 | F13: 1995 | G13: 2024 | H13: NA | I13: OK
A14: West | B14: US_RR_177 | C14: WATL | D14: 2 | E14: 2 | F14: 1993 | G14: 2024 | H14: NA | I14: OK
A15: West | B15: US_RR_145 | C15: WATL | D15: 2 | E15: 2 | F15: 1980 | G15: 1992 | H15: 1984 | I15: OK
A16: West | B16: US_RR_195 | C16: WATL | D16: 2 | E16: 2 | F16: 1983 | G16: 1992 | H16: NA | I16: OK
A17: West | B17: MEXUS_GOM_PLL | C17: GOM | D17: 1 | E17: 1 | F17: 1994 | G17: 2024 | H17: NA | I17: OK
A18: West | B18: JPN_LL_West1 | C18: WATL | D18: 2 | E18: 2 | F18: 1976 | G18: 2009 | H18: NA | I18: OK
A19: West | B19: JPN_LL_West2 | C19: WATL | D19: 2 | E19: 2 | F19: 2010 | G19: 2024 | H19: NA | I19: OK
A20: West | B20: JPLL_GOM | C20: GOM | D20: 1 | E20: 1 | F20: 1974 | G20: 1981 | H20: NA | I20: OK
A21: West | B21: CAN SWNS | C21: WATL | D21: 2 | E21: 2 | F21: 1996 | G21: 2024 | H21: NA | I21: OK
A22: West | B22: GOM_LAR_SUV | C22: GOM | D22: 1 | E22: 1 | F22: 1974 | G22: 2024 | H22: 1975, 1977, 2020, 2022 | I22: OK
A23: West | B23: CAN_ACO_SUV1 | C23: WATL | D23: 2 | E23: 3 | F23: 1994 | G23: 2017 | H23: NA | I23: OK
A24: West | B24: CAN_ACO_SUV2 | C24: WATL | D24: 2 | E24: 3 | F24: 2018 | G24: 2019 | H24: NA | I24: OK
A25: West | B25: US_RR_66_114 | C25: WATL | D25: 2 | E25: 2 | F25: 1995 | G25: 2020 | H25: NA | I25: we don’t use it, can we remove?
A26: West | B26: US_RR_115_144 | C26: WATL | D26: 2 | E26: 2 | F26: 1995 | G26: 2020 | H26: NA | I26: we don’t use it, can we remove?
A27: West | B27: CAN combined RR | C27: WATL | D27: 2 | E27: 2 | F27: 1984 | G27: 2018 | H27: NA | I27: we don’t use it, can we remove?
... A30: West | B30: CAN GSL | C30: WATL | D30: 2 | E30: 3 | F30: 1988 | G30: 2022 | H30: NA | I30: we don’t use it, can we remove?
A34: Sensitivity only
A35: East/West | B35: Revised/New indices | C35: Details | D35: Selectivity
A36: East | B36: VAST_JPN_LL_NEAtl1 | C36: 1995-2009 | I36: OK
A37: East | B37: VAST_JPN_LL_NEAtl2 | C37: 2010-2024, Q4, N Atl | D37: 18: LLJPNnew | I37: OK
A38: East | B38: sdmTMB_POR-MOR_TRAP | C38: 2008-2024, Q2-Q3, E Atl | D38: TRAP | I38: OK
A39: East | B39: Balfegó_PS | C39: 2003-2025 | D39: SSB average weight limitis (75-200kg)
A40: East | B40: Larval_fitness_index | C40: 1982-2025 | D40: SSB
A41: West | B41: VAST_JPN_LL_West1 | C41: 1977-2008 | I41: OK
A42: West | B42: VAST_JPN_LL_West2 | C42: 2010-2024, Q4, W Atl | D42: 18: LLJPNnew | I42: OK
A43: West | B43: VAST_CAN_SWNS_RR | C43: 1996-2024, Q3-Q4; WATL | D43: RRCAN (145-240 kg, 194-232 cm) | I43: OK
A44: West | B44: VAST_CAN_GSL_RR | C44: 1996-2024, Q3-Q4; GSL | D44: RRCAN (240-370 kg, 232-270 cm) | I44: OK
A45: West | B45: VAST_US_RR_177 | C45: 2002-2022, Q3, W Atl | D45: 16: RRUSAFB (175cm+) | I45: OK
...

Sheet CPUE
A1: Year | B1: Season | C1: Area | D1: Fleet | E1: Index | F1: CV | G1: Len_cat | H1: Name
A2: 1952 | B2: 3 | C2: 3 | D2: 3 | E2: 179.22 | F2: 0.425 | G2: 0 | H2: SPN_BB
A3: 1953 | B3: 3 | C3: 3 | D3: 3 | E3: 184.74 | F3: 0.53 | G3: 0 | H3: SPN_BB
A4: 1954 | B4: 3 | C4: 3 | D4: 3 | E4: 226.46 | F4: 0.414 | G4: 0 | H4: SPN_BB
A5: 1955 | B5: 3 | C5: 3 | D5: 3 | E5: 187.01 | F5: 0.423 | G5: 0 | H5: SPN_BB
A6: 1956 | B6: 3 | C6: 3 | D6: 3 | E6: 470.53 | F6: 0.431 | G6: 0 | H6: SPN_BB
A7: 1957 | B7: 3 | C7: 3 | D7: 3 | E7: 315.05 | F7: 0.411 | G7: 0 | H7: SPN_BB
A8: 1958 | B8: 3 | C8: 3 | D8: 3 | E8: 252.25 | F8: 0.409 | G8: 0 | H8: SPN_BB
A9: 1959 | B9: 3 | C9: 3 | D9: 3 | E9: 506.79 | F9: 0.412 | G9: 0 | H9: SPN_BB
A10: 1960 | B10: 3 | C10: 3 | D10: 3 | E10: 485.16 | F10: 0.425 | G10: 0 | H10: SPN_BB
A11: 1961 | B11: 3 | C11: 3 | D11: 3 | E11: 327.29 | F11: 0.413 | G11: 0 | H11: SPN_BB
A12: 1962 | B12: 3 | C12: 3 | D12: 3 | E12: 180.12 | F12: 0.462 | G12: 0 | H12: SPN_BB
A13: 1963 | B13: 3 | C13: 3 | D13: 3 | E13: 312.09 | F13: 0.493 | G13: 0 | H13: SPN_BB
... A105: 2021 | B105: 2 | C105: 3 | D105: 13 | E105: 172 | F105: 0.301 | G105: 0 | H105: MOR_POR_TRAP
A106: 2022 | B106: 2 | C106: 3 | D106: 13 | E106: 139.6 | F106: NA | G106: 0 | H106: MOR_POR_TRAP
A107: 1975 | B107: 2 | C107: 3 | D107: 2 | E107: 1.9 | F107: 0.15 | G107: 0 | H107: JPN_LL_Eatl_Med
A108: 1976 | B108: 2 | C108: 3 | D108: 2 | E108: 2.15 | F108: 0.12 | G108: 0 | H108: JPN_LL_Eatl_Med
A109: 1977 | B109: 2 | C109: 3 | D109: 2 | E109: 3.53 | F109: 0.14 | G109: 0 | H109: JPN_LL_Eatl_Med
A110: 1978 | B110: 2 | C110: 3 | D110: 2 | E110: 1.5 | F110: 0.15 | G110: 0 | H110: JPN_LL_Eatl_Med
A111: 1979 | B111: 2 | C111: 3 | D111: 2 | E111: 2.7 | F111: 0.14 | G111: 0 | H111: JPN_LL_Eatl_Med
A112: 1980 | B112: 2 | C112: 3 | D112: 2 | E112: 1.69 | F112: 0.16 | G112: 0 | H112: JPN_LL_Eatl_Med
A113: 1981 | B113: 2 | C113: 3 | D113: 2 | E113: 1.63 | F113: 0.17 | G113: 0 | H113: JPN_LL_Eatl_Med
A114: 1982 | B114: 2 | C114: 3 | D114: 2 | E114: 3.32 | F114: 0.13 | G114: 0 | H114: JPN_LL_Eatl_Med
A115: 1983 | B115: 2 | C115: 3 | D115: 2 | E115: 2.12 | F115: 0.13 | G115: 0 | H115: JPN_LL_Eatl_Med
A116: 1984 | B116: 2 | C116: 3 | D116: 2 | E116: 1.62 | F116: 0.12 | G116: 0 | H116: JPN_LL_Eatl_Med
A117: 1985 | B117: 2 | C117: 3 | D117: 2 | E117: 1.75 | F117: 0.15 | G117: 0 | H117: JPN_LL_Eatl_Med
A118: 1986 | B118: 2 | C118: 3 | D118: 2 | E118: 1.32 | F118: 0.14 | G118: 0 | H118: JPN_LL_Eatl_Med
... A176: 2024 | B176: 4 | C176: 3 | D176: 18 | E176: 5.4 | F176: 0.168 | G176: 0 | H176: JPN_LL_NEAtl2
A177: 1995 | B177: 3 | C177: 2 | D177: 15 | E177: 1.1172234 | F177: 0.12408059 | H177: US_RR_66_144
A178: 1996 | B178: 3 | C178: 2 | D178: 15 | E178: 1.2455873 | F178: 0.12387791 | H178: US_RR_66_144
A179: 1997 | B179: 3 | C179: 2 | D179: 15 | E179: 1.8200402 | F179: 0.10072364 | H179: US_RR_66_144
A180: 1998 | B180: 3 | C180: 2 | D180: 15 | E180: 0.8926786 | F180: 0.10196868 | H180: US_RR_66_144
A181: 1999 | B181: 3 | C181: 2 | D181: 15 | E181: 0.85114829 | F181: 0.17438342 | H181: US_RR_66_144
A182: 2000 | B182: 3 | C182: 2 | D182: 15 | E182: 1.1042363 | F182: 0.18121409 | H182: US_RR_66_144
A183: 2001 | B183: 3 | C183: 2 | D183: 15 | E183: 0.70481454 | F183: 0.11370779 | H183: US_RR_66_144
A184: 2002 | B184: 3 | C184: 2 | D184: 15 | E184: 0.97082445 | F184: 0.15026271 | H184: US_RR_66_144
A185: 2003 | B185: 3 | C185: 2 | D185: 15 | E185: 0.60195837 | F185: 0.087980139 | H185: US_RR_66_144
A186: 2004 | B186: 3 | C186: 2 | D186: 15 | E186: 1.4893592 | F186: 0.091588035 | H186: US_RR_66_144
A187: 2005 | B187: 3 | C187: 2 | D187: 15 | E187: 1.4571016 | F187: 0.10560537 | H187: US_RR_66_144
A188: 2006 | B188: 3 | C188: 2 | D188: 15 | E188: 0.66739644 | F188: 0.16258466 | H188: US_RR_66_144
...

Sheet Survey
A1: Year | B1: Season | C1: Area | D1: Stock | E1: Type | F1: Index | G1: CV | H1: Name
A2: 2000 | B2: 3 | C2: 4 | D2: 1 | E2: B | F2: 0.02 | G2: 0.38 | H2: FR_AER_SUV1
A3: 2001 | B3: 3 | C3: 4 | D3: 1 | E3: B | F3: 0.01 | G3: 0.37 | H3: FR_AER_SUV1
A4: 2002 | B4: 3 | C4: 4 | D4: 1 | E4: B | F4: 0.01 | G4: 0.49 | H4: FR_AER_SUV1
A5: 2003 | B5: 3 | C5: 4 | D5: 1 | E5: B | F5: 0.01 | G5: 0.31 | H5: FR_AER_SUV1
A6: 2009 | B6: 3 | C6: 4 | D6: 1 | E6: B | F6: 0.0181352 | G6: 0.35191988 | H6: FR_AER_SUV2
A7: 2010 | B7: 3 | C7: 4 | D7: 1 | E7: B | F7: 0.0141675 | G7: 0.52547763 | H7: FR_AER_SUV2
A8: 2011 | B8: 3 | C8: 4 | D8: 1 | E8: B | F8: 0.0264543 | G8: 0.25023492 | H8: FR_AER_SUV2
A9: 2012 | B9: 3 | C9: 4 | D9: 1 | E9: B | F9: 0.0179826 | G9: 0.26661795 | H9: FR_AER_SUV2
A10: 2013 | B10: 3 | C10: 4 | D10: 1 | E10: B | F10: NA | G10: NA | H10: FR_AER_SUV2
A11: 2014 | B11: 3 | C11: 4 | D11: 1 | E11: B | F11: 0.0633515 | G11: 0.27059864 | H11: FR_AER_SUV2
A12: 2015 | B12: 3 | C12: 4 | D12: 1 | E12: B | F12: 0.027394 | G12: 0.24088584 | H12: FR_AER_SUV2
A13: 2016 | B13: 3 | C13: 4 | D13: 1 | E13: B | F13: 0.1074406 | G13: 0.20039094 | H13: FR_AER_SUV2
A14: 2017 | B14: 3 | C14: 4 | D14: 1 | E14: B | F14: 0.0686392 | G14: 0.2465831 | H14: FR_AER_SUV2
A15: 2018 | B15: 3 | C15: 4 | D15: 1 | E15: B | F15: 0.0308929 | G15: 0.17281646 | H15: FR_AER_SUV2
A16: 2019 | B16: 3 | C16: 4 | D16: 1 | E16: B | F16: 0.0625227 | G16: 0.140099 | H16: FR_AER_SUV2
A17: 2020 | B17: 3 | C17: 4 | D17: 1 | E17: B | F17: 0.1356895 | G17: 0.15042079 | H17: FR_AER_SUV2
A18: 2021 | B18: 3 | C18: 4 | D18: 1 | E18: B | F18: 0.0974964 | G18: 0.14480961 | H18: FR_AER_SUV2
A19: 2022 | B19: 3 | C19: 4 | D19: 1 | E19: B | F19: 0.0543768 | G19: 0.2634105 | H19: FR_AER_SUV2
A20: 2023 | B20: 3 | C20: 4 | D20: 1 | E20: B | F20: 0.1011568 | G20: 0.29 | H20: FR_AER_SUV2
A21: 2024 | B21: 3 | C21: 4 | D21: 1 | E21: B | F21: 0.0570973 | G21: 0.1604473 | H21: FR_AER_SUV2
A22: 2001 | B22: 2 | C22: 4 | D22: 1 | E22: SB | F22: 5 | G22: 0.41 | H22: MED_LAR_SUV
... A26: 2005 | B26: 2 | C26: 4 | D26: 1 | E26: SB | F26: 2.34 | G26: 0.38 | H26: MED_LAR_SUV
A27: 2006 | B27: 2 | C27: 4 | D27: 1 | E27: SB | F27: NA | G27: NA | H27: MED_LAR_SUV
A28: 2007 | B28: 2 | C28: 4 | D28: 1 | E28: SB | F28: NA | G28: NA | H28: MED_LAR_SUV
A29: 2008 | B29: 2 | C29: 4 | D29: 1 | E29: SB | F29: 2.21 | G29: 0.77 | H29: MED_LAR_SUV
A30: 2009 | B30: 2 | C30: 4 | D30: 1 | E30: SB | F30: NA | G30: NA | H30: MED_LAR_SUV
A31: 2010 | B31: 2 | C31: 4 | D31: 1 | E31: SB | F31: NA | G31: NA | H31: MED_LAR_SUV
A32: 2011 | B32: 2 | C32: 4 | D32: 1 | E32: SB | F32: 10.52 | G32: 0.4 | H32: MED_LAR_SUV
A33: 2012 | B33: 2 | C33: 4 | D33: 1 | E33: SB | F33: 30.07 | G33: 0.2 | H33: MED_LAR_SUV
A34: 2013 | B34: 2 | C34: 4 | D34: 1 | E34: SB | F34: 43.61 | G34: 0.3 | H34: MED_LAR_SUV
A35: 2014 | B35: 2 | C35: 4 | D35: 1 | E35: SB | F35: 22.98 | G35: 0.29 | H35: MED_LAR_SUV
A36: 2015 | B36: 2 | C36: 4 | D36: 1 | E36: SB | F36: 40.41 | G36: 0.23 | H36: MED_LAR_SUV
A37: 2016 | B37: 2 | C37: 4 | D37: 1 | E37: SB | F37: 33.48 | G37: 0.28 | H37: MED_LAR_SUV
A38: 2017 | B38: 2 | C38: 4 | D38: 1 | E38: SB | F38: 80.03 | G38: 0.24 | H38: MED_LAR_SUV
A39: 2018 | B39: 2 | C39: 4 | D39: 1 | E39: SB | F39: NA | G39: NA | H39: MED_LAR_SUV
A40: 2019 | B40: 2 | C40: 4 | D40: 1 | E40: SB | F40: 51 | G40: 0.24 | H40: MED_LAR_SUV
A41: 2020 | B41: 2 | C41: 4 | D41: 1 | E41: SB | F41: 114.95 | G41: 0.22 | H41: MED_LAR_SUV
A42: 2021 | B42: 2 | C42: 4 | D42: 1 | E42: SB | F42: NA | G42: NA | H42: MED_LAR_SUV
A43: 2022 | B43: 2 | C43: 4 | D43: 1 | E43: SB | F43: 51 | G43: 0.25 | H43: MED_LAR_SUV
...

Sheet E_Tag
A1: Stock | B1: Age_class | C1: Season | D1: From_Area | E1: To_Area | F1: Number | G1: Fraction
A2: 2 | B2: 3 | C2: 2 | D2: 1 | E2: 1 | F2: 37 | G2: 0.90243902
A3: 2 | B3: 3 | C3: 3 | D3: 1 | E3: 1 | F3: 2 | G3: 0.086956522
A4: 2 | B4: 3 | C4: 1 | D4: 1 | E4: 1 | F4: 7 | G4: 1

Sheet Length_Comp
A1: Year | B1: Season | C1: Area | D1: Fleet | E1: Len_class | F1: N
A2: 1984 | B2: 1 | C2: 1 | D2: 1 | E2: 8 | F2: 24
A3: 1984 | B3: 1 | C3: 1 | D3: 1 | E3: 9 | F3: 39
A4: 1984 | B4: 1 | C4: 1 | D4: 1 | E4: 10 | F4: 34
A5: 1984 | B5: 1 | C5: 1 | D5: 1 | E5: 11 | F5: 2
A6: 1985 | B6: 1 | C6: 1 | D6: 1 | E6: 7 | F6: 2
A7: 1985 | B7: 1 | C7: 1 | D7: 1 | E7: 8 | F7: 15
A8: 1985 | B8: 2 | C8: 1 | D8: 1 | E8: 8 | F8: 7
A9: 1985 | B9: 1 | C9: 1 | D9: 1 | E9: 9 | F9: 29
A10: 1985 | B10: 2 | C10: 1 | D10: 1 | E10: 9 | F10: 27
A11: 1985 | B11: 1 | C11: 1 | D11: 1 | E11: 10 | F11: 15
A12: 1985 | B12: 2 | C12: 1 | D12: 1 | E12: 10 | F12: 8
A13: 1985 | B13: 1 | C13: 1 | D13: 1 | E13: 11 | F13: 4
... A10162: 2024 | B10162: 4 | C10162: 3 | D10162: 18 | E10162: 11 | F10162: 3

Sheet SOO
A1: Year | B1: Age_class | C1: Area | D1: Season | E1: Method | F1: Prob_Stock_1 | G1: N | H1: SE
A2: 46 | B2: 3 | C2: 2 | D2: 3 | E2: Otolith Chemistry | F2: 0.242 | G2: 12 | H2: 0.352
A3: 46 | B3: 3 | C3: 2 | D3: 3 | E3: Otolith Chemistry | F3: 0.384 | G3: 5 | H3: 0.228
A4: 46 | B4: 3 | C4: 2 | D4: 3 | E4: Otolith Chemistry | F4: 0.982 | G4: 2 | H4: 0.651

Sheet CKMR_POP
A1: Stock | B1: Year_i | C1: Year_j | D1: Age_i | E1: Age_j | F1: Season_i | G1: Season_j | H1: Area_i | I1: Area_j | J1: n | K1: N
A2: Yet to be confirmed by M. Lauretta
M4: i = parent
M5: j = offspring
M6: Year = year sampled
M7: Age = age at sample time
M8: Season = season sampled
M9: Area = area sampled
M10: n = number of POP
M11: N = number of comparisons

Sheet CKMR_HSP
A1: Stock | B1: Year_i | C1: Year_j | D1: Age_i | E1: Age_j | F1: Season_i | G1: Season_j | H1: Area_i | I1: Area_j | J1: n | K1: N
A2: Yet to be confirmed by M. Lauretta
M4: i = older sibling
M5: j = younger sibling
M6: Year = year sampled
M7: Age = age at sample time
M8: Season = season sampled
M9: Area = area sampled
M10: n = number of HSP
M11: N = number of comparisons

Sheet CPUE_Vuln
A1: Min_len_class | B1: Max_len_class
A2: 2 | B2: 4
A3: 4 | B3: 5
A4: 7 | B4: 15
A5: 2 | B5: 5
A6: 7 | B6: 15
A7: 2 | B7: 5

Sheet Seasonal_Prior
A1: Year | B1: Season | C1: Area | D1: Ino | E1: Index | F1: CV | G1: Min_len_class | H1: Max_len_class
A2: 1 | B2: 1 | C2: 1 | D2: 1 | E2: 0.31 | F2: 0.025 | G2: 5 | H2: 15
A3: 1 | B3: 2 | C3: 1 | D3: 1 | E3: 0.61 | F3: 0.025 | G3: 5 | H3: 15
A4: 1 | B4: 3 | C4: 1 | D4: 1 | E4: 0.07 | F4: 0.025 | G4: 5 | H4: 15
A5: 1 | B5: 4 | C5: 1 | D5: 1 | E5: 0.01 | F5: 0.025 | G5: 5 | H5: 15
A6: 1 | B6: 1 | C6: 4 | D6: 2 | E6: 0.15 | F6: 0.025 | G6: 5 | H6: 15
A7: 1 | B7: 2 | C7: 4 | D7: 2 | E7: 0.53 | F7: 0.025 | G7: 5 | H7: 15
A8: 1 | B8: 3 | C8: 4 | D8: 2 | E8: 0.18 | F8: 0.025 | G8: 5 | H8: 15
A9: 1 | B9: 4 | C9: 4 | D9: 2 | E9: 0.15 | F9: 0.025 | G9: 5 | H9: 15

Sheet Fleets
A1: Number | B1: Code | C1: Min_length | D1: Max_length | E1: Selectivity | F1: Selectivity_index
A2: 1 | B2: LLOTH | C2: 12.5 | D2: 412.5 | E2: Dome | F2: 1
A3: 2 | B3: LLJPN | C3: 12.5 | D3: 362.5 | E3: Dome | F3: 2
A4: 3 | B4: BBold | C4: 12.5 | D4: 237.5 | E4: Dome | F4: 3
A5: 4 | B5: BBnew | C5: 12.5 | D5: 287.5 | E5: Dome | F5: 4
A6: 5 | B6: PSMEDold | C6: 12.5 | D6: 362.5 | E6: Dome | F6: 5
A7: 6 | B7: PSMEDoldQ2 | C7: 12.5 | D7: 312.5 | E7: Dome | F7: 6
A8: 7 | B8: PSMEDnew | C8: 12.5 | D8: 362.5 | E8: Dome | F8: 7
A9: 8 | B9: PSNOR | C9: 112.5 | D9: 337.5 | E9: Dome | F9: 8
A10: 9 | B10: PSHRV | C10: 12.5 | D10: 287.5 | E10: Dome | F10: 9
A11: 10 | B11: PSWold | C11: 12.5 | D11: 337.5 | E11: Dome | F11: 10
A12: 11 | B12: PSWnew | C12: 62.5 | D12: 312.5 | E12: Dome | F12: 11
A13: 12 | B13: TPold | C13: 37.5 | D13: 337.5 | E13: Dome | F13: 12
... A19: 18 | B19: LLJPNnew | C19: 62.5 | D19: 312.5 | E19: Dome | F19: 18

Sheet Age_classes
A1: Age | B1: Class
A2: 1 | B2: 1
A3: 2 | B3: 1
A4: 3 | B4: 1
A5: 4 | B5: 1
A6: 5 | B6: 2
A7: 6 | B7: 2
A8: 7 | B8: 2
A9: 8 | B9: 2
A10: 9 | B10: 3
A11: 10 | B11: 3
A12: 11 | B12: 3
A13: 12 | B13: 3
... A36: 35 | B36: 3

Sheet Seasons
A1: Season | B1: Code | C1: Duration
A2: 1 | B2: Q1 | C2: 0.25
A3: 2 | B3: Q2 | C3: 0.25
A4: 3 | B4: Q3 | C4: 0.25
A5: 4 | B5: Q4 | C5: 0.25

Sheet Areas
A1: Area | B1: Name | C1: Type | D1: Coordinates
A2: 1 | B2: GOM | C2: Longitude | D2: -100,-95,-88,-80,-80,-85,-100
A3: 1 | B3: GOM | C3: Latitude | D3: 20,17,20,20,25,35,35
A4: 2 | B4: WATL | C4: Longitude | D4: -70,-95 ,-88,-80,-80,-85,-70,-70,-80,-100,-100,-45,-45,-30,-30,-25,-25,-70
A5: 2 | B5: WATL | C5: Latitude | D5: 0, 16.5,20,20,25,35,45,55,50,60,80,80,10,10,5,5,-50,-50
A6: 3 | B6: EATL | C6: Longitude | D6: -30,-45,-45, 45, 45, 15, 15, 5, -5, -5, 20, 20, -25,-25,-30
A7: 3 | B7: EATL | C7: Latitude | D7: 10,10,80,80,60,60,50,50,40,30,30,-50,-50,5,5
A8: 4 | B8: MED | C8: Longitude | D8: -5,45,45,5,-5
A9: 4 | B9: MED | C9: Latitude | D9: 30,30,50,50,40

Sheet Length_classes
A1: Number | B1: LengthClass
A2: 1 | B2: 25
A3: 2 | B3: 50
A4: 3 | B4: 75
A5: 4 | B5: 100
A6: 5 | B6: 125
A7: 6 | B7: 150
A8: 7 | B8: 175
A9: 8 | B9: 200
A10: 9 | B10: 225
A11: 10 | B11: 250
A12: 11 | B12: 275
A13: 12 | B13: 300
... A17: 16 | B17: 400

Sheet LAA
A1: Age | B1: Eastern | C1: Western
A2: 1 | B2: 53.377629 | C2: 48.051759
A3: 2 | B3: 76.953301 | C3: 65.798606
A4: 3 | B4: 98.4353 | C4: 85.431278
A5: 4 | B5: 118.00956 | C5: 105.98995
A6: 5 | B6: 135.84549 | C6: 126.53534
A7: 6 | B7: 152.09748 | C7: 146.2746
A8: 7 | B8: 166.90619 | C8: 164.62563
A9: 8 | B9: 180.39979 | C9: 181.2269
A10: 9 | B10: 192.69507 | C10: 195.91125
A11: 10 | B11: 203.89845 | C11: 208.66262
A12: 11 | B12: 214.10689 | C12: 219.56987
A13: 12 | B13: 223.40876 | C13: 228.78593
... A36: 35 | B36: 307.60964 | C36: 270.67223

Sheet CV_LAA
A1: Age | B1: Eastern | C1: Western
A2: 1 | B2: =(LAA!B2*0.06+5.84)/LAA!B2 -> 0.16940913 | C2: =(LAA!C2*0.06+5.84)/LAA!C2 -> 0.18153561
A3: 2 | B3: =(LAA!B3*0.06+5.84)/LAA!B3 -> 0.13589018 | C3: =(LAA!C3*0.06+5.84)/LAA!C3 -> 0.14875568
A4: 3 | B4: =(LAA!B4*0.06+5.84)/LAA!B4 -> 0.11932831 | C4: =(LAA!C4*0.06+5.84)/LAA!C4 -> 0.12835904
A5: 4 | B5: =(LAA!B5*0.06+5.84)/LAA!B5 -> 0.10948752 | C5: =(LAA!C5*0.06+5.84)/LAA!C5 -> 0.11509956
A6: 5 | B6: =(LAA!B6*0.06+5.84)/LAA!B6 -> 0.10299002 | C6: =(LAA!C6*0.06+5.84)/LAA!C6 -> 0.10615311
A7: 6 | B7: =(LAA!B7*0.06+5.84)/LAA!B7 -> 0.098396427 | C7: =(LAA!C7*0.06+5.84)/LAA!C7 -> 0.099924908
A8: 7 | B8: =(LAA!B8*0.06+5.84)/LAA!B8 -> 0.094989715 | C8: =(LAA!C8*0.06+5.84)/LAA!C8 -> 0.095474427
A9: 8 | B9: =(LAA!B9*0.06+5.84)/LAA!B9 -> 0.092372543 | C9: =(LAA!C9*0.06+5.84)/LAA!C9 -> 0.092224797
A10: 9 | B10: =(LAA!B10*0.06+5.84)/LAA!B10 -> 0.090306951 | C10: =(LAA!C10*0.06+5.84)/LAA!C10 -> 0.089809416
A11: 10 | B11: =(LAA!B11*0.06+5.84)/LAA!B11 -> 0.088641709 | C11: =(LAA!C11*0.06+5.84)/LAA!C11 -> 0.087987763
A12: 11 | B12: =(LAA!B12*0.06+5.84)/LAA!B12 -> 0.087276095 | C12: =(LAA!C12*0.06+5.84)/LAA!C12 -> 0.086597456
A13: 12 | B13: =(LAA!B13*0.06+5.84)/LAA!B13 -> 0.086140425 | C13: =(LAA!C13*0.06+5.84)/LAA!C13 -> 0.085526045
... A36: 35 | B36: =(LAA!B36*0.06+5.84)/LAA!B36 -> 0.078985101 | C36: =(LAA!C36*0.06+5.84)/LAA!C36 -> 0.081575911

Sheet WAA
A1: Age | B1: Eastern | C1: Western
A2: 1 | B2: 3.2898785 | C2: 1.9739635
A3: 2 | B3: 9.4291717 | C3: 5.0702833
A4: 3 | B4: 19.153491 | C4: 11.101325
A5: 4 | B5: 32.282927 | C5: 21.204864
A6: 5 | B6: 48.409102 | C6: 36.088866
A7: 6 | B7: 67.018108 | C7: 55.76007
A8: 7 | B8: 87.566675 | C8: 79.501104
A9: 8 | B9: 109.52813 | C9: 106.07206
A10: 9 | B10: 132.41857 | C10: 134.01504
A11: 10 | B11: 155.8101 | C11: 161.9361
A12: 11 | B12: 179.33577 | C12: 188.69293
A13: 12 | B13: 202.68921 | C13: 213.47534
... A36: 35 | B36: 508.91675 | C36: 353.57557

Sheet Maturity
A1: Age | B1: Eastern | C1: Western
A2: 1 | B2: 0 | C2: 0
A3: 2 | B3: 0 | C3: 0
A4: 3 | B4: 0.25 | C4: 0.25
A5: 4 | B5: 0.5 | C5: 0.5
A6: 5 | B6: 1 | C6: 1
A7: 6 | B7: 1 | C7: 1
A8: 7 | B8: 1 | C8: 1
A9: 8 | B9: 1 | C9: 1
A10: 9 | B10: 1 | C10: 1
A11: 10 | B11: 1 | C11: 1
A12: 11 | B12: 1 | C12: 1
A13: 12 | B13: 1 | C13: 1
... A36: 35 | B36: 1 | C36: 1

Sheet SRR
A1: Number | B1: Stock | C1: Min_year | D1: Max_year | E1: Steepness
A2: 1 | B2: 1 | C2: 1965 | D2: 1987 | E2: 0.98
A3: 2 | B3: 1 | C3: =C2+24-1 -> 1988 | D3: 2019 | E3: 0.98
A4: 3 | B4: 2 | C4: 1965 | D4: 1974 | E4: 0.6
A5: 4 | B5: 3 | C5: =1965+11-1 -> 1975 | D5: 2019 | E5: 0.9

Sheet Spawn_timing
A1: Season | B1: Eastern | C1: Western
A2: 1 | B2: 0 | C2: 0
A3: 2 | B3: 1 | C3: 1
A4: 3 | B4: 0 | C4: 0
A5: 4 | B5: 0 | C5: 0

Sheet Spawn_areas
A1: Area | B1: Eastern | C1: Western
A2: 1 | B2: 0 | C2: 1
A3: 2 | B3: 0 | C3: 1
A4: 3 | B4: 0 | C4: 0
A5: 4 | B5: 1 | C5: 0

Sheet MAA
A1: Age | B1: Eastern | C1: Western
A2: 1 | B2: 0.38 | C2: 0.38
A3: 2 | B3: 0.3 | C3: 0.3
A4: 3 | B4: 0.24 | C4: 0.24
A5: 4 | B5: 0.2 | C5: 0.2
A6: 5 | B6: 0.18 | C6: 0.18
A7: 6 | B7: 0.16 | C7: 0.16
A8: 7 | B8: 0.14 | C8: 0.14
A9: 8 | B9: 0.13 | C9: 0.13
A10: 9 | B10: 0.12 | C10: 0.12
A11: 10 | B11: 0.12 | C11: 0.12
A12: 11 | B12: 0.11 | C12: 0.11
A13: 12 | B13: 0.11 | C13: 0.11
... A36: 35 | B36: 0.1 | C36: 0.1

Sheet Mov_Exc
A1: Stock | B1: Age_class | C1: Season | D1: From_area | E1: To_area | F1: Gravity
A2: 1 | B2: 1 | C2: 1 | D2: 1 | E2: 1 | F2: -20
A3: 1 | B3: 2 | C3: 1 | D3: 1 | E3: 1 | F3: -20
A4: 1 | B4: 3 | C4: 1 | D4: 1 | E4: 1 | F4: -20
